[31m[1mERROR   [0m apilogger:reply_data.py:111 è¡¨æ ¼å†™å…¥æŠ¥é”™